Traceback (most recent call last):
  File "/usr/local/lib/python3.10/runpy.py", line 196, in _run_module_as_main
    return _run_code(code, main_globals, None,
  File "/usr/local/lib/python3.10/runpy.py", line 86, in _run_code
    exec(code, run_globals)
  File "/app/main.py", line 18, in <module>
    raise ValueError("Broken file")
ValueError: Broken file
